<?xml version="1.0" ?>
<!-- =================================================================================== -->
<!-- |    This document was autogenerated by xacro from /home/liujin/work/shixi/src/dual_ur_description/urdf/dual_ur10_robot.urdf.xacro | -->
<!-- |    EDITING THIS FILE BY HAND IS NOT RECOMMENDED                                 | -->
<!-- =================================================================================== -->
<robot name="ur10" xmlns:xacro="http://wiki.ros.org/xacro">
    <gazebo>
        <plugin filename="libgazebo_ros_control.so" name="ros_control">
            <!--robotNamespace>/</robotNamespace-->
            <!--robotSimType>gazebo_ros_control/DefaultRobotHWSim</robotSimType-->
        </plugin>
        <!--
    <plugin name="gazebo_ros_power_monitor_controller" filename="libgazebo_ros_power_monitor.so">
      <alwaysOn>true</alwaysOn>
      <updateRate>1.0</updateRate>
      <timeout>5</timeout>
      <powerStateTopic>power_state</powerStateTopic>
      <powerStateRate>10.0</powerStateRate>
      <fullChargeCapacity>87.78</fullChargeCapacity>     
      <dischargeRate>-474</dischargeRate>
      <chargeRate>525</chargeRate>
      <dischargeVoltage>15.52</dischargeVoltage>
      <chargeVoltage>16.41</chargeVoltage>
    </plugin>
-->
    </gazebo>
    <!--
  Author: Kelsey Hawkins
  Contributers: Jimmy Da Silva, Ajit Krisshna N L, Muhammad Asif Rana
-->
    <!-- measured from model -->
    <link name="left_base_link">
        <visual>
            <geometry>
                <mesh filename="package://dual_ur_description/meshes/ur10/visual/base.dae" />
            </geometry>
            <material name="LightGrey">
                <color rgba="0.7 0.7 0.7 1.0" />
            </material>
        </visual>
        <collision>
            <geometry>
                <mesh filename="package://dual_ur_description/meshes/ur10/collision/base.stl" />
            </geometry>
        </collision>
        
<inertial>
            <mass value="4.0" />
            <origin rpy="0 0 0" xyz="0.0 0.0 0.0" />
            <inertia ixx="0.0061063308908" ixy="0.0" ixz="0.0" iyy="0.0061063308908" iyz="0.0" izz="0.01125" />
        </inertial>

    </link>
    <joint name="left_shoulder_pan_joint" type="revolute">
        <parent link="left_base_link" />
        <child link="left_shoulder_link" />
        <origin rpy="0.0 0.0 0.0" xyz="0.0 0.0 0.1273" />
        <axis xyz="0 0 1" />
        <limit effort="330.0" lower="-6.28318530718" upper="6.28318530718" velocity="2.16" />
        <dynamics damping="0.0" friction="0.0" />
    </joint>
    <link name="left_shoulder_link">
        <visual>
            <geometry>
                <mesh filename="package://dual_ur_description/meshes/ur10/visual/shoulder.dae" />
            </geometry>
            <material name="LightGrey">
                <color rgba="0.7 0.7 0.7 1.0" />
            </material>
        </visual>
        <collision>
            <geometry>
                <mesh filename="package://dual_ur_description/meshes/ur10/collision/shoulder.stl" />
            </geometry>
        </collision>
        
<inertial>
            <mass value="7.778" />
            <origin rpy="0 0 0" xyz="0.0 0.0 0.0" />
            <inertia ixx="0.0314743125769" ixy="0.0" ixz="0.0" iyy="0.0314743125769" iyz="0.0" izz="0.021875625" />
        </inertial>

    </link>
    <joint name="left_shoulder_lift_joint" type="revolute">
        <parent link="left_shoulder_link" />
        <child link="left_upper_arm_link" />
        <origin rpy="0.0 1.57079632679 0.0" xyz="0.0 0.220941 0.0" />
        <axis xyz="0 1 0" />
        <limit effort="330.0" lower="-6.28318530718" upper="6.28318530718" velocity="2.16" />
        <dynamics damping="0.0" friction="0.0" />
    </joint>
    <link name="left_upper_arm_link">
        <visual>
            <geometry>
                <mesh filename="package://dual_ur_description/meshes/ur10/visual/upperarm.dae" />
            </geometry>
            <material name="LightGrey">
                <color rgba="0.7 0.7 0.7 1.0" />
            </material>
        </visual>
        <collision>
            <geometry>
                <mesh filename="package://dual_ur_description/meshes/ur10/collision/upperarm.stl" />
            </geometry>
        </collision>
        
<inertial>
            <mass value="12.93" />
            <origin rpy="0 0 0" xyz="0.0 0.0 0.306" />
            <inertia ixx="0.421753803798" ixy="0.0" ixz="0.0" iyy="0.421753803798" iyz="0.0" izz="0.036365625" />
        </inertial>

    </link>
    <joint name="left_elbow_joint" type="revolute">
        <parent link="left_upper_arm_link" />
        <child link="left_forearm_link" />
        <origin rpy="0.0 0.0 0.0" xyz="0.0 -0.1719 0.612" />
        <axis xyz="0 1 0" />
        <limit effort="150.0" lower="-3.14159265359" upper="3.14159265359" velocity="3.15" />
        <dynamics damping="0.0" friction="0.0" />
    </joint>
    <link name="left_forearm_link">
        <visual>
            <geometry>
                <mesh filename="package://dual_ur_description/meshes/ur10/visual/forearm.dae" />
            </geometry>
            <material name="LightGrey">
                <color rgba="0.7 0.7 0.7 1.0" />
            </material>
        </visual>
        <collision>
            <geometry>
                <mesh filename="package://dual_ur_description/meshes/ur10/collision/forearm.stl" />
            </geometry>
        </collision>
        
<inertial>
            <mass value="3.87" />
            <origin rpy="0 0 0" xyz="0.0 0.0 0.28615" />
            <inertia ixx="0.111069694097" ixy="0.0" ixz="0.0" iyy="0.111069694097" iyz="0.0" izz="0.010884375" />
        </inertial>

    </link>
    <joint name="left_wrist_1_joint" type="revolute">
        <parent link="left_forearm_link" />
        <child link="left_wrist_1_link" />
        <origin rpy="0.0 1.57079632679 0.0" xyz="0.0 0.0 0.5723" />
        <axis xyz="0 1 0" />
        <limit effort="54.0" lower="-6.28318530718" upper="6.28318530718" velocity="3.2" />
        <dynamics damping="0.0" friction="0.0" />
    </joint>
    <link name="left_wrist_1_link">
        <visual>
            <geometry>
                <mesh filename="package://dual_ur_description/meshes/ur10/visual/wrist1.dae" />
            </geometry>
            <material name="LightGrey">
                <color rgba="0.7 0.7 0.7 1.0" />
            </material>
        </visual>
        <collision>
            <geometry>
                <mesh filename="package://dual_ur_description/meshes/ur10/collision/wrist1.stl" />
            </geometry>
        </collision>
        
<inertial>
            <mass value="1.96" />
            <origin rpy="0 0 0" xyz="0.0 0.0 0.0" />
            <inertia ixx="0.0051082479567" ixy="0.0" ixz="0.0" iyy="0.0051082479567" iyz="0.0" izz="0.0055125" />
        </inertial>

    </link>
    <joint name="left_wrist_2_joint" type="revolute">
        <parent link="left_wrist_1_link" />
        <child link="left_wrist_2_link" />
        <origin rpy="0.0 0.0 0.0" xyz="0.0 0.1149 0.0" />
        <axis xyz="0 0 1" />
        <limit effort="54.0" lower="-6.28318530718" upper="6.28318530718" velocity="3.2" />
        <dynamics damping="0.0" friction="0.0" />
    </joint>
    <link name="left_wrist_2_link">
        <visual>
            <geometry>
                <mesh filename="package://dual_ur_description/meshes/ur10/visual/wrist2.dae" />
            </geometry>
            <material name="LightGrey">
                <color rgba="0.7 0.7 0.7 1.0" />
            </material>
        </visual>
        <collision>
            <geometry>
                <mesh filename="package://dual_ur_description/meshes/ur10/collision/wrist2.stl" />
            </geometry>
        </collision>
        
<inertial>
            <mass value="1.96" />
            <origin rpy="0 0 0" xyz="0.0 0.0 0.0" />
            <inertia ixx="0.0051082479567" ixy="0.0" ixz="0.0" iyy="0.0051082479567" iyz="0.0" izz="0.0055125" />
        </inertial>

    </link>
    <joint name="left_wrist_3_joint" type="revolute">
        <parent link="left_wrist_2_link" />
        <child link="left_wrist_3_link" />
        <origin rpy="0.0 0.0 0.0" xyz="0.0 0.0 0.1157" />
        <axis xyz="0 1 0" />
        <limit effort="54.0" lower="-6.28318530718" upper="6.28318530718" velocity="3.2" />
        <dynamics damping="0.0" friction="0.0" />
    </joint>
    <link name="left_wrist_3_link">
        <visual>
            <geometry>
                <mesh filename="package://dual_ur_description/meshes/ur10/visual/wrist3.dae" />
            </geometry>
            <material name="LightGrey">
                <color rgba="0.7 0.7 0.7 1.0" />
            </material>
        </visual>
        <collision>
            <geometry>
                <mesh filename="package://dual_ur_description/meshes/ur10/collision/wrist3.stl" />
            </geometry>
        </collision>
        
<inertial>
            <mass value="0.202" />
            <origin rpy="0 0 0" xyz="0.0 0.0 0.0" />
            <inertia ixx="0.000526462289415" ixy="0.0" ixz="0.0" iyy="0.000526462289415" iyz="0.0" izz="0.000568125" />
        </inertial>

    </link>
    <joint name="left_ee_fixed_joint" type="fixed">
        <parent link="left_wrist_3_link" />
        <child link="left_ee_link" />
        <origin rpy="0.0 0.0 1.57079632679" xyz="0.0 0.0922 0.0" />
    </joint>
    <link name="left_ee_link">
        <collision>
            <geometry>
                <box size="0.01 0.01 0.01" />
            </geometry>
            <origin rpy="0 0 0" xyz="-0.01 0 0" />
        </collision>
        
<inertial>
            <mass value="0.1" />
            <inertia ixx="0.03" iyy="0.03" izz="0.03" ixy="0.0" ixz="0.0" iyz="0.0" />
        </inertial>

    </link>
    <transmission name="left_shoulder_pan_trans">
        <type>transmission_interface/SimpleTransmission</type>
        <joint name="left_shoulder_pan_joint">
            <hardwareInterface>hardware_interface/PositionJointInterface</hardwareInterface>
        </joint>
        <actuator name="left_shoulder_pan_motor">
            <mechanicalReduction>1</mechanicalReduction>
        </actuator>
    </transmission>
    <transmission name="left_shoulder_lift_trans">
        <type>transmission_interface/SimpleTransmission</type>
        <joint name="left_shoulder_lift_joint">
            <hardwareInterface>hardware_interface/PositionJointInterface</hardwareInterface>
        </joint>
        <actuator name="left_shoulder_lift_motor">
            <mechanicalReduction>1</mechanicalReduction>
        </actuator>
    </transmission>
    <transmission name="left_elbow_trans">
        <type>transmission_interface/SimpleTransmission</type>
        <joint name="left_elbow_joint">
            <hardwareInterface>hardware_interface/PositionJointInterface</hardwareInterface>
        </joint>
        <actuator name="left_elbow_motor">
            <mechanicalReduction>1</mechanicalReduction>
        </actuator>
    </transmission>
    <transmission name="left_wrist_1_trans">
        <type>transmission_interface/SimpleTransmission</type>
        <joint name="left_wrist_1_joint">
            <hardwareInterface>hardware_interface/PositionJointInterface</hardwareInterface>
        </joint>
        <actuator name="left_wrist_1_motor">
            <mechanicalReduction>1</mechanicalReduction>
        </actuator>
    </transmission>
    <transmission name="left_wrist_2_trans">
        <type>transmission_interface/SimpleTransmission</type>
        <joint name="left_wrist_2_joint">
            <hardwareInterface>hardware_interface/PositionJointInterface</hardwareInterface>
        </joint>
        <actuator name="left_wrist_2_motor">
            <mechanicalReduction>1</mechanicalReduction>
        </actuator>
    </transmission>
    <transmission name="left_wrist_3_trans">
        <type>transmission_interface/SimpleTransmission</type>
        <joint name="left_wrist_3_joint">
            <hardwareInterface>hardware_interface/PositionJointInterface</hardwareInterface>
        </joint>
        <actuator name="left_wrist_3_motor">
            <mechanicalReduction>1</mechanicalReduction>
        </actuator>
    </transmission>
    <gazebo reference="left_shoulder_link">
        <selfCollide>true</selfCollide>
    </gazebo>
    <gazebo reference="left_upper_arm_link">
        <selfCollide>true</selfCollide>
    </gazebo>
    <gazebo reference="left_forearm_link">
        <selfCollide>true</selfCollide>
    </gazebo>
    <gazebo reference="left_wrist_1_link">
        <selfCollide>true</selfCollide>
    </gazebo>
    <gazebo reference="left_wrist_3_link">
        <selfCollide>true</selfCollide>
    </gazebo>
    <gazebo reference="left_wrist_2_link">
        <selfCollide>true</selfCollide>
    </gazebo>
    <gazebo reference="left_ee_link">
        <selfCollide>true</selfCollide>
    </gazebo>
    <!-- ROS base_link to UR 'Base' Coordinates transform -->
    <link name="left_base" />
    <joint name="left_base_link-base_fixed_joint" type="fixed">
        <!-- NOTE: this rotation is only needed as long as base_link itself is
                 not corrected wrt the real robot (ie: rotated over 180
                 degrees)
      -->
        <origin rpy="0 0 -3.14159265359" xyz="0 0 0" />
        <parent link="left_base_link" />
        <child link="left_base" />
    </joint>
    <!-- Frame coincident with all-zeros TCP on UR controller -->
    <link name="left_tool0" />
    <joint name="left_wrist_3_link-tool0_fixed_joint" type="fixed">
        <origin rpy="-1.57079632679 0 0" xyz="0 0.0922 0" />
        <parent link="left_wrist_3_link" />
        <child link="left_tool0" />
    </joint>
    <!-- measured from model -->
    <link name="right_base_link">
        <visual>
            <geometry>
                <mesh filename="package://dual_ur_description/meshes/ur10/visual/base.dae" />
            </geometry>
            <material name="LightGrey">
                <color rgba="0.7 0.7 0.7 1.0" />
            </material>
        </visual>
        <collision>
            <geometry>
                <mesh filename="package://dual_ur_description/meshes/ur10/collision/base.stl" />
            </geometry>
        </collision>
        
<inertial>
            <mass value="4.0" />
            <origin rpy="0 0 0" xyz="0.0 0.0 0.0" />
            <inertia ixx="0.0061063308908" ixy="0.0" ixz="0.0" iyy="0.0061063308908" iyz="0.0" izz="0.01125" />
        </inertial>

    </link>
    <joint name="right_shoulder_pan_joint" type="revolute">
        <parent link="right_base_link" />
        <child link="right_shoulder_link" />
        <origin rpy="0.0 0.0 0.0" xyz="0.0 0.0 0.1273" />
        <axis xyz="0 0 1" />
        <limit effort="330.0" lower="-6.28318530718" upper="6.28318530718" velocity="2.16" />
        <dynamics damping="0.0" friction="0.0" />
    </joint>
    <link name="right_shoulder_link">
        <visual>
            <geometry>
                <mesh filename="package://dual_ur_description/meshes/ur10/visual/shoulder.dae" />
            </geometry>
            <material name="LightGrey">
                <color rgba="0.7 0.7 0.7 1.0" />
            </material>
        </visual>
        <collision>
            <geometry>
                <mesh filename="package://dual_ur_description/meshes/ur10/collision/shoulder.stl" />
            </geometry>
        </collision>
        
<inertial>
            <mass value="7.778" />
            <origin rpy="0 0 0" xyz="0.0 0.0 0.0" />
            <inertia ixx="0.0314743125769" ixy="0.0" ixz="0.0" iyy="0.0314743125769" iyz="0.0" izz="0.021875625" />
        </inertial>

    </link>
    <joint name="right_shoulder_lift_joint" type="revolute">
        <parent link="right_shoulder_link" />
        <child link="right_upper_arm_link" />
        <origin rpy="0.0 1.57079632679 0.0" xyz="0.0 0.220941 0.0" />
        <axis xyz="0 1 0" />
        <limit effort="330.0" lower="-6.28318530718" upper="6.28318530718" velocity="2.16" />
        <dynamics damping="0.0" friction="0.0" />
    </joint>
    <link name="right_upper_arm_link">
        <visual>
            <geometry>
                <mesh filename="package://dual_ur_description/meshes/ur10/visual/upperarm.dae" />
            </geometry>
            <material name="LightGrey">
                <color rgba="0.7 0.7 0.7 1.0" />
            </material>
        </visual>
        <collision>
            <geometry>
                <mesh filename="package://dual_ur_description/meshes/ur10/collision/upperarm.stl" />
            </geometry>
        </collision>
        
<inertial>
            <mass value="12.93" />
            <origin rpy="0 0 0" xyz="0.0 0.0 0.306" />
            <inertia ixx="0.421753803798" ixy="0.0" ixz="0.0" iyy="0.421753803798" iyz="0.0" izz="0.036365625" />
        </inertial>

    </link>
    <joint name="right_elbow_joint" type="revolute">
        <parent link="right_upper_arm_link" />
        <child link="right_forearm_link" />
        <origin rpy="0.0 0.0 0.0" xyz="0.0 -0.1719 0.612" />
        <axis xyz="0 1 0" />
        <limit effort="150.0" lower="-3.14159265359" upper="3.14159265359" velocity="3.15" />
        <dynamics damping="0.0" friction="0.0" />
    </joint>
    <link name="right_forearm_link">
        <visual>
            <geometry>
                <mesh filename="package://dual_ur_description/meshes/ur10/visual/forearm.dae" />
            </geometry>
            <material name="LightGrey">
                <color rgba="0.7 0.7 0.7 1.0" />
            </material>
        </visual>
        <collision>
            <geometry>
                <mesh filename="package://dual_ur_description/meshes/ur10/collision/forearm.stl" />
            </geometry>
        </collision>
        
<inertial>
            <mass value="3.87" />
            <origin rpy="0 0 0" xyz="0.0 0.0 0.28615" />
            <inertia ixx="0.111069694097" ixy="0.0" ixz="0.0" iyy="0.111069694097" iyz="0.0" izz="0.010884375" />
        </inertial>

    </link>
    <joint name="right_wrist_1_joint" type="revolute">
        <parent link="right_forearm_link" />
        <child link="right_wrist_1_link" />
        <origin rpy="0.0 1.57079632679 0.0" xyz="0.0 0.0 0.5723" />
        <axis xyz="0 1 0" />
        <limit effort="54.0" lower="-6.28318530718" upper="6.28318530718" velocity="3.2" />
        <dynamics damping="0.0" friction="0.0" />
    </joint>
    <link name="right_wrist_1_link">
        <visual>
            <geometry>
                <mesh filename="package://dual_ur_description/meshes/ur10/visual/wrist1.dae" />
            </geometry>
            <material name="LightGrey">
                <color rgba="0.7 0.7 0.7 1.0" />
            </material>
        </visual>
        <collision>
            <geometry>
                <mesh filename="package://dual_ur_description/meshes/ur10/collision/wrist1.stl" />
            </geometry>
        </collision>
        
<inertial>
            <mass value="1.96" />
            <origin rpy="0 0 0" xyz="0.0 0.0 0.0" />
            <inertia ixx="0.0051082479567" ixy="0.0" ixz="0.0" iyy="0.0051082479567" iyz="0.0" izz="0.0055125" />
        </inertial>

    </link>
    <joint name="right_wrist_2_joint" type="revolute">
        <parent link="right_wrist_1_link" />
        <child link="right_wrist_2_link" />
        <origin rpy="0.0 0.0 0.0" xyz="0.0 0.1149 0.0" />
        <axis xyz="0 0 1" />
        <limit effort="54.0" lower="-6.28318530718" upper="6.28318530718" velocity="3.2" />
        <dynamics damping="0.0" friction="0.0" />
    </joint>
    <link name="right_wrist_2_link">
        <visual>
            <geometry>
                <mesh filename="package://dual_ur_description/meshes/ur10/visual/wrist2.dae" />
            </geometry>
            <material name="LightGrey">
                <color rgba="0.7 0.7 0.7 1.0" />
            </material>
        </visual>
        <collision>
            <geometry>
                <mesh filename="package://dual_ur_description/meshes/ur10/collision/wrist2.stl" />
            </geometry>
        </collision>
        
<inertial>
            <mass value="1.96" />
            <origin rpy="0 0 0" xyz="0.0 0.0 0.0" />
            <inertia ixx="0.0051082479567" ixy="0.0" ixz="0.0" iyy="0.0051082479567" iyz="0.0" izz="0.0055125" />
        </inertial>

    </link>
    <joint name="right_wrist_3_joint" type="revolute">
        <parent link="right_wrist_2_link" />
        <child link="right_wrist_3_link" />
        <origin rpy="0.0 0.0 0.0" xyz="0.0 0.0 0.1157" />
        <axis xyz="0 1 0" />
        <limit effort="54.0" lower="-6.28318530718" upper="6.28318530718" velocity="3.2" />
        <dynamics damping="0.0" friction="0.0" />
    </joint>
    <link name="right_wrist_3_link">
        <visual>
            <geometry>
                <mesh filename="package://dual_ur_description/meshes/ur10/visual/wrist3.dae" />
            </geometry>
            <material name="LightGrey">
                <color rgba="0.7 0.7 0.7 1.0" />
            </material>
        </visual>
        <collision>
            <geometry>
                <mesh filename="package://dual_ur_description/meshes/ur10/collision/wrist3.stl" />
            </geometry>
        </collision>
        
<inertial>
            <mass value="0.202" />
            <origin rpy="0 0 0" xyz="0.0 0.0 0.0" />
            <inertia ixx="0.000526462289415" ixy="0.0" ixz="0.0" iyy="0.000526462289415" iyz="0.0" izz="0.000568125" />
        </inertial>

    </link>
    <joint name="right_ee_fixed_joint" type="fixed">
        <parent link="right_wrist_3_link" />
        <child link="right_ee_link" />
        <origin rpy="0.0 0.0 1.57079632679" xyz="0.0 0.0922 0.0" />
    </joint>
    <link name="right_ee_link">
        <collision>
            <geometry>
                <box size="0.01 0.01 0.01" />
            </geometry>
            <origin rpy="0 0 0" xyz="-0.01 0 0" />
        </collision>
        
<inertial>
            <mass value="0.1" />
            <inertia ixx="0.03" iyy="0.03" izz="0.03" ixy="0.0" ixz="0.0" iyz="0.0" />
        </inertial>

    </link>
    <transmission name="right_shoulder_pan_trans">
        <type>transmission_interface/SimpleTransmission</type>
        <joint name="right_shoulder_pan_joint">
            <hardwareInterface>hardware_interface/PositionJointInterface</hardwareInterface>
        </joint>
        <actuator name="right_shoulder_pan_motor">
            <mechanicalReduction>1</mechanicalReduction>
        </actuator>
    </transmission>
    <transmission name="right_shoulder_lift_trans">
        <type>transmission_interface/SimpleTransmission</type>
        <joint name="right_shoulder_lift_joint">
            <hardwareInterface>hardware_interface/PositionJointInterface</hardwareInterface>
        </joint>
        <actuator name="right_shoulder_lift_motor">
            <mechanicalReduction>1</mechanicalReduction>
        </actuator>
    </transmission>
    <transmission name="right_elbow_trans">
        <type>transmission_interface/SimpleTransmission</type>
        <joint name="right_elbow_joint">
            <hardwareInterface>hardware_interface/PositionJointInterface</hardwareInterface>
        </joint>
        <actuator name="right_elbow_motor">
            <mechanicalReduction>1</mechanicalReduction>
        </actuator>
    </transmission>
    <transmission name="right_wrist_1_trans">
        <type>transmission_interface/SimpleTransmission</type>
        <joint name="right_wrist_1_joint">
            <hardwareInterface>hardware_interface/PositionJointInterface</hardwareInterface>
        </joint>
        <actuator name="right_wrist_1_motor">
            <mechanicalReduction>1</mechanicalReduction>
        </actuator>
    </transmission>
    <transmission name="right_wrist_2_trans">
        <type>transmission_interface/SimpleTransmission</type>
        <joint name="right_wrist_2_joint">
            <hardwareInterface>hardware_interface/PositionJointInterface</hardwareInterface>
        </joint>
        <actuator name="right_wrist_2_motor">
            <mechanicalReduction>1</mechanicalReduction>
        </actuator>
    </transmission>
    <transmission name="right_wrist_3_trans">
        <type>transmission_interface/SimpleTransmission</type>
        <joint name="right_wrist_3_joint">
            <hardwareInterface>hardware_interface/PositionJointInterface</hardwareInterface>
        </joint>
        <actuator name="right_wrist_3_motor">
            <mechanicalReduction>1</mechanicalReduction>
        </actuator>
    </transmission>
    <gazebo reference="right_shoulder_link">
        <selfCollide>true</selfCollide>
    </gazebo>
    <gazebo reference="right_upper_arm_link">
        <selfCollide>true</selfCollide>
    </gazebo>
    <gazebo reference="right_forearm_link">
        <selfCollide>true</selfCollide>
    </gazebo>
    <gazebo reference="right_wrist_1_link">
        <selfCollide>true</selfCollide>
    </gazebo>
    <gazebo reference="right_wrist_3_link">
        <selfCollide>true</selfCollide>
    </gazebo>
    <gazebo reference="right_wrist_2_link">
        <selfCollide>true</selfCollide>
    </gazebo>
    <gazebo reference="right_ee_link">
        <selfCollide>true</selfCollide>
    </gazebo>
    <!-- ROS base_link to UR 'Base' Coordinates transform -->
    <link name="right_base" />
    <joint name="right_base_link-base_fixed_joint" type="fixed">
        <!-- NOTE: this rotation is only needed as long as base_link itself is
                 not corrected wrt the real robot (ie: rotated over 180
                 degrees)
      -->
        <origin rpy="0 0 -3.14159265359" xyz="0 0 0" />
        <parent link="right_base_link" />
        <child link="right_base" />
    </joint>
    <!-- Frame coincident with all-zeros TCP on UR controller -->
    <link name="right_tool0" />
    <joint name="right_wrist_3_link-tool0_fixed_joint" type="fixed">
        <origin rpy="-1.57079632679 0 0" xyz="0 0.0922 0" />
        <parent link="right_wrist_3_link" />
        <child link="right_tool0" />
    </joint>
    <link name="world" />
    <joint name="left_world_joint" type="fixed">
        <parent link="world" />
        <child link="left_base_link" />
        <origin rpy="0.0 0.0 0.0" xyz="0.0 -0.7 0.0" />
    </joint>
    <joint name="right_world_joint" type="fixed">
        <parent link="world" />
        <child link="right_base_link" />
        <origin rpy="0.0 0.0 0.0" xyz="0.0 0.7 0.0" />
    </joint>
</robot>

